Workbook
Name Slicer_country: #N/A
Name Slicer_region: #N/A
Name Slicer_year: #N/A

Sheet Graphs
A3: Avg_EV_Range | C3: EV Market Share | E3: Total EV Sales | H3: Total ICE Sales
A4: 265.8725 | C4: 0.065043365 | E4: 76322837 | H4: 1097091799

Sheet dashboard
A2: Avg_EV_Range | C2: EV Market Share | E2: Total EV Sales | G2: Total ICE Sales
A3: 265.8725 | C3: 0.065043365 | E3: 76322837 | G3: 1097091799

Sheet master raw data
A1: country | B1: region | C1: year | D1: vehicle_segment | E1: powertrain_type | F1: ev_sales | G1: petrol_car_sales | H1: diesel_car_sales | I1: total_vehicle_sales | J1: ev_market_share | K1: charging_stations | L1: fast_chargers_share | M1: avg_ev_range_km | N1: fuel_price_usd_per_liter | O1: electricity_price_usd_per_kwh | P1: gdp_per_capita | Q1: urban_population_percent | R1: co2_emissions_transport_mt | S1: ev_subsidy_usd | T1: emission_regulation_score | U1: ev_growth_rate_yoy | V1: is_ev_dominant
A2: Australia | B2: Oceania | C2: 2010 | D2: commercial | E2: ICE | F2: 5 | G2: 92877 | H2: 61921 | I2: 154803 | J2: 0 | K2: 0 | L2: 0 | M2: 124 | N2: 1.09 | O2: 0.149 | P2: 51977 | Q2: 88.8 | R2: 88.7 | S2: 0 | T2: 30.4 | U2: 0 | V2: 0
A3: Australia | B3: Oceania | C3: 2010 | D3: mass_market | E3: ICE | F3: 57 | G3: 535933 | H3: 73089 | I3: 609079 | J3: 0.01 | K3: 0 | L3: 0 | M3: 124 | N3: 1.09 | O3: 0.149 | P3: 51977 | Q3: 88.8 | R3: 88.7 | S3: 0 | T3: 30.4 | U3: 0 | V3: 0
A4: Australia | B4: Oceania | C4: 2010 | D4: premium | E4: ICE | F4: 37 | G4: 235282 | H4: 20462 | I4: 255781 | J4: 0.01 | K4: 0 | L4: 0 | M4: 124 | N4: 1.09 | O4: 0.149 | P4: 51977 | Q4: 88.8 | R4: 88.7 | S4: 0 | T4: 30.4 | U4: 0 | V4: 0
A5: Australia | B5: Oceania | C5: 2011 | D5: commercial | E5: ICE | F5: 11 | G5: 98092 | H5: 65395 | I5: 163498 | J5: 0.01 | K5: 105 | L5: 1.5 | M5: 133 | N5: 1.09 | O5: 0.163 | P5: 52807 | Q5: 88.9 | R5: 88.3 | S5: 0 | T5: 30.8 | U5: 120 | V5: 0
A6: Australia | B6: Oceania | C6: 2011 | D6: mass_market | E6: ICE | F6: 129 | G6: 569679 | H6: 77684 | I6: 647492 | J6: 0.02 | K6: 105 | L6: 1.5 | M6: 133 | N6: 1.09 | O6: 0.163 | P6: 52807 | Q6: 88.9 | R6: 88.3 | S6: 0 | T6: 30.8 | U6: 126.32 | V6: 0
A7: Australia | B7: Oceania | C7: 2011 | D7: premium | E7: ICE | F7: 80 | G7: 252643 | H7: 21969 | I7: 274692 | J7: 0.03 | K7: 105 | L7: 1.5 | M7: 133 | N7: 1.09 | O7: 0.163 | P7: 52807 | Q7: 88.9 | R7: 88.3 | S7: 0 | T7: 30.8 | U7: 116.22 | V7: 0
A8: Australia | B8: Oceania | C8: 2012 | D8: commercial | E8: ICE | F8: 17 | G8: 96466 | H8: 64310 | I8: 160793 | J8: 0.01 | K8: 191 | L8: 3.3 | M8: 135 | N8: 1.067 | O8: 0.177 | P8: 54075 | Q8: 88.5 | R8: 89.5 | S8: 0 | T8: 31.6 | U8: 84.39 | V8: 0
A9: Australia | B9: Oceania | C9: 2012 | D9: mass_market | E9: ICE | F9: 195 | G9: 571555 | H9: 77939 | I9: 649689 | J9: 0.03 | K9: 191 | L9: 3.3 | M9: 135 | N9: 1.067 | O9: 0.177 | P9: 54075 | Q9: 88.5 | R9: 89.5 | S9: 0 | T9: 31.6 | U9: 51.16 | V9: 0
A10: Australia | B10: Oceania | C10: 2012 | D10: premium | E10: ICE | F10: 117 | G10: 246448 | H10: 21430 | I10: 267995 | J10: 0.04 | K10: 191 | L10: 3.3 | M10: 135 | N10: 1.067 | O10: 0.177 | P10: 54075 | Q10: 88.5 | R10: 89.5 | S10: 0 | T10: 31.6 | U10: 77.82 | V10: 0
A11: Australia | B11: Oceania | C11: 2013 | D11: commercial | E11: ICE | F11: 36 | G11: 101461 | H11: 67640 | I11: 169137 | J11: 0.02 | K11: 306 | L11: 5 | M11: 143 | N11: 1.033 | O11: 0.192 | P11: 55582 | Q11: 89.6 | R11: 90 | S11: 0 | T11: 33.2 | U11: 93.1 | V11: 0
A12: Australia | B12: Oceania | C12: 2013 | D12: mass_market | E12: ICE | F12: 400 | G12: 586920 | H12: 80035 | I12: 667355 | J12: 0.06 | K12: 306 | L12: 5 | M12: 143 | N12: 1.033 | O12: 0.192 | P12: 55582 | Q12: 89.6 | R12: 90 | S12: 0 | T12: 33.2 | U12: 105.13 | V12: 0
A13: Australia | B13: Oceania | C13: 2013 | D13: premium | E13: ICE | F13: 242 | G13: 256088 | H13: 22269 | I13: 278599 | J13: 0.09 | K13: 306 | L13: 5 | M13: 143 | N13: 1.033 | O13: 0.192 | P13: 55582 | Q13: 89.6 | R13: 90 | S13: 0 | T13: 33.2 | U13: 106.84 | V13: 0
... A709: Norway | B709: Europe | C709: 2021 | D709: premium | E709: BEV | F709: 42451 | G709: 2055 | H709: 179 | I709: 44685 | J709: 95 | K709: 19829 | L709: 30.1 | M709: 395 | N709: 2.063 | O709: 0.131 | P709: 95275 | Q709: 82.8 | R709: 7.7 | S709: 0 | T709: 92.2 | U709: 51.45 | V709: 1
A710: Norway | B710: Europe | C710: 2022 | D710: commercial | E710: ICE | F710: 7229 | G710: 9462 | H710: 6308 | I710: 22999 | J710: 31.43 | K710: 24419 | L710: 31.8 | M710: 420 | N710: 2.143 | O710: 0.159 | P710: 103437 | Q710: 83.4 | R710: 7.2 | S710: 0 | T710: 95.60199999999999 | U710: 15.61 | V710: 0
A711: Norway | B711: Europe | C711: 2022 | D711: mass_market | E711: BEV | F711: 82306 | G711: 8218 | H711: 1121 | I711: 91645 | J711: 89.81 | K711: 24419 | L711: 31.8 | M711: 420 | N711: 2.143 | O711: 0.159 | P711: 103437 | Q711: 83.4 | R711: 7.2 | S711: 0 | T711: 95.60199999999999 | U711: 14.06 | V711: 1
A712: Norway | B712: Europe | C712: 2022 | D712: premium | E712: BEV | F712: 36110 | G712: 1748 | H712: 152 | I712: 38010 | J712: 95 | K712: 24419 | L712: 31.8 | M712: 420 | N712: 2.143 | O712: 0.159 | P712: 103437 | Q712: 83.4 | R712: 7.2 | S712: 0 | T712: 95.60199999999999 | U712: -14.94 | V712: 1
A713: Norway | B713: Europe | C713: 2023 | D713: commercial | E713: ICE | F713: 6780 | G713: 9069 | H713: 6804 | I713: 22653 | J713: 29.93 | K713: 29628 | L713: 32.9 | M713: 442 | N713: 2.153 | O713: 0.168 | P713: 100025 | Q713: 83.5 | R713: 6.7 | S713: 0 | T713: 95.6 | U713: -6.21 | V713: 0
A714: Norway | B714: Europe | C714: 2023 | D714: mass_market | E714: BEV | F714: 79933 | G714: 7450 | H714: 3131 | I714: 90514 | J714: 88.31 | K714: 29628 | L714: 32.9 | M714: 442 | N714: 2.153 | O714: 0.168 | P714: 100025 | Q714: 83.5 | R714: 6.7 | S714: 0 | T714: 95.6 | U714: -2.88 | V714: 1
A715: Norway | B715: Europe | C715: 2023 | D715: premium | E715: BEV | F715: 35655 | G715: 1727 | H715: 150 | I715: 37532 | J715: 95 | K715: 29628 | L715: 32.9 | M715: 442 | N715: 2.153 | O715: 0.168 | P715: 100025 | Q715: 83.5 | R715: 6.7 | S715: 0 | T715: 95.6 | U715: -1.26 | V715: 1
A716: Norway | B716: Europe | C716: 2024 | D716: commercial | E716: ICE | F716: 6792 | G716: 10069 | H716: 6713 | I716: 23574 | J716: 28.81 | K716: 33158 | L716: 31.7 | M716: 481 | N716: 2.09 | O716: 0.155 | P716: 94974 | Q716: 83.5 | R716: 6 | S716: 0 | T716: 95.60199999999999 | U716: 0.18 | V716: 0
A717: Norway | B717: Europe | C717: 2024 | D717: mass_market | E717: BEV | F717: 82124 | G717: 10471 | H717: 2007 | I717: 94602 | J717: 86.81 | K717: 33158 | L717: 31.7 | M717: 481 | N717: 2.09 | O717: 0.155 | P717: 94974 | Q717: 83.5 | R717: 6 | S717: 0 | T717: 95.60199999999999 | U717: 2.74 | V717: 1
A718: Norway | B718: Europe | C718: 2024 | D718: premium | E718: BEV | F718: 36884 | G718: 1786 | H718: 155 | I718: 38825 | J718: 95 | K718: 33158 | L718: 31.7 | M718: 481 | N718: 2.09 | O718: 0.155 | P718: 94974 | Q718: 83.5 | R718: 6 | S718: 0 | T718: 95.60199999999999 | U718: 3.45 | V718: 1
A719: Norway | B719: Europe | C719: 2025 | D719: commercial | E719: ICE | F719: 7082 | G719: 9845 | H719: 6563 | I719: 23490 | J719: 30.15 | K719: 35915 | L719: 32.2 | M719: 507 | N719: 2.04 | O719: 0.144 | P719: 96351 | Q719: 84.3 | R719: 5.4 | S719: 0 | T719: 95.60199999999999 | U719: 4.27 | V719: 0
A720: Norway | B720: Europe | C720: 2025 | D720: mass_market | E720: BEV | F720: 80945 | G720: 11461 | H720: 1563 | I720: 93969 | J720: 86.14 | K720: 35915 | L720: 32.2 | M720: 507 | N720: 2.04 | O720: 0.144 | P720: 96351 | Q720: 84.3 | R720: 5.4 | S720: 0 | T720: 95.60199999999999 | U720: -1.44 | V720: 1
A721: Norway | B721: Europe | C721: 2025 | D721: premium | E721: BEV | F721: 37238 | G721: 1803 | H721: 157 | I721: 39198 | J721: 95 | K721: 35915 | L721: 32.2 | M721: 507 | N721: 2.04 | O721: 0.144 | P721: 96351 | Q721: 84.3 | R721: 5.4 | S721: 0 | T721: 95.60199999999999 | U721: 0.96 | V721: 1
A722: Poland | B722: Europe | C722: 2010 | D722: commercial | E722: ICE | F722: 5 | G722: 30458 | H722: 20309 | I722: 50772 | J722: 0.01 | K722: 0 | L722: 0 | M722: 111 | N722: 1.26 | O722: 0.143 | P722: 12774 | Q722: 60.9 | R722: 42.9 | S722: 0 | T722: 35.5 | U722: 0 | V722: 0
A723: Poland | B723: Europe | C723: 2010 | D723: mass_market | E723: ICE | F723: 15 | G723: 179802 | H723: 24520 | I723: 204337 | J723: 0.01 | K723: 0 | L723: 0 | M723: 111 | N723: 1.26 | O723: 0.143 | P723: 12774 | Q723: 60.9 | R723: 42.9 | S723: 0 | T723: 35.5 | U723: 0 | V723: 0
A724: Poland | B724: Europe | C724: 2010 | D724: premium | E724: ICE | F724: 10 | G724: 77444 | H724: 6735 | I724: 84189 | J724: 0.01 | K724: 0 | L724: 0 | M724: 111 | N724: 1.26 | O724: 0.143 | P724: 12774 | Q724: 60.9 | R724: 42.9 | S724: 0 | T724: 35.5 | U724: 0 | V724: 0
A725: Poland | B725: Europe | C725: 2011 | D725: commercial | E725: ICE | F725: 5 | G725: 30688 | H725: 20461 | I725: 51154 | J725: 0.01 | K725: 33 | L725: 1.1 | M725: 133 | N725: 1.22 | O725: 0.142 | P725: 12432 | Q725: 60.4 | R725: 43.5 | S725: 461 | T725: 36.3 | U725: 0 | V725: 0
A726: Poland | B726: Europe | C726: 2011 | D726: mass_market | E726: ICE | F726: 20 | G726: 179407 | H726: 24465 | I726: 203892 | J726: 0.01 | K726: 33 | L726: 1.1 | M726: 133 | N726: 1.22 | O726: 0.142 | P726: 12432 | Q726: 60.4 | R726: 43.5 | S726: 461 | T726: 36.3 | U726: 33.33 | V726: 0
A727: Poland | B727: Europe | C727: 2011 | D727: premium | E727: ICE | F727: 12 | G727: 76516 | H727: 6654 | I727: 83182 | J727: 0.01 | K727: 33 | L727: 1.1 | M727: 133 | N727: 1.22 | O727: 0.142 | P727: 12432 | Q727: 60.4 | R727: 43.5 | S727: 461 | T727: 36.3 | U727: 20 | V727: 0
A728: Poland | B728: Europe | C728: 2012 | D728: commercial | E728: ICE | F728: 10 | G728: 29335 | H728: 19562 | I728: 48907 | J728: 0.02 | K728: 69 | L728: 1.9 | M728: 148 | N728: 1.187 | O728: 0.14 | P728: 12537 | Q728: 60.5 | R728: 44.9 | S728: 908 | T728: 37.8 | U728: 41.42 | V728: 0
A729: Poland | B729: Europe | C729: 2012 | D729: mass_market | E729: ICE | F729: 39 | G729: 170818 | H729: 23293 | I729: 194150 | J729: 0.02 | K729: 69 | L729: 1.9 | M729: 148 | N729: 1.187 | O729: 0.14 | P729: 12537 | Q729: 60.5 | R729: 44.9 | S729: 908 | T729: 37.8 | U729: 61.25 | V729: 0
A730: Poland | B730: Europe | C730: 2012 | D730: premium | E730: ICE | F730: 24 | G730: 75579 | H730: 6572 | I730: 82175 | J730: 0.03 | K730: 69 | L730: 1.9 | M730: 148 | N730: 1.187 | O730: 0.14 | P730: 12537 | Q730: 60.5 | R730: 44.9 | S730: 908 | T730: 37.8 | U730: 54.92 | V730: 0
A731: Poland | B731: Europe | C731: 2013 | D731: commercial | E731: ICE | F731: 8 | G731: 29076 | H731: 19388 | I731: 48472 | J731: 0.02 | K731: 108 | L731: 3.2 | M731: 130 | N731: 1.153 | O731: 0.139 | P731: 12431 | Q731: 60.7 | R731: 46 | S731: 1382 | T731: 39.9 | U731: 16.96 | V731: 0
A732: Poland | B732: Europe | C732: 2013 | D732: mass_market | E732: ICE | F732: 39 | G732: 172737 | H732: 23555 | I732: 196331 | J732: 0.02 | K732: 108 | L732: 3.2 | M732: 130 | N732: 1.153 | O732: 0.139 | P732: 12431 | Q732: 60.7 | R732: 46 | S732: 1382 | T732: 39.9 | U732: 37.51 | V732: 0
A733: Poland | B733: Europe | C733: 2013 | D733: premium | E733: ICE | F733: 24 | G733: 75395 | H733: 6556 | I733: 81975 | J733: 0.03 | K733: 108 | L733: 3.2 | M733: 130 | N733: 1.153 | O733: 0.139 | P733: 12431 | Q733: 60.7 | R733: 46 | S733: 1382 | T733: 39.9 | U733: 33.89 | V733: 0
... A958: Sweden | B958: Europe | C958: 2024 | D958: premium | E958: BEV | F958: 54057 | G958: 18104 | H958: 1574 | I958: 73735 | J958: 73.31 | K958: 35576 | L958: 26.7 | M958: 466 | N958: 2 | O958: 0.155 | P958: 57305 | Q958: 88.8 | R958: 13.2 | S958: 0 | T958: 92.7 | U958: 5.44 | V958: 1
A959: Sweden | B959: Europe | C959: 2025 | D959: commercial | E959: ICE | F959: 8259 | G959: 22172 | H959: 14781 | I959: 45212 | J959: 18.27 | K959: 45844 | L959: 26.6 | M959: 486 | N959: 1.93 | O959: 0.141 | P959: 61242 | Q959: 89 | R959: 12.2 | S959: 0 | T959: 95.60199999999999 | U959: 6.62 | V959: 0
...

Sheet cards
A2: Total EV Sales | B2: =SUM('master raw data'!F:F) -> 76322837
A3: EV Market Share | B3: =SUM('master raw data'!F:F)/SUM('master raw data'!I:I) -> 0.065043365
A4: Total Charging Stations | B4: =SUM('master raw data'!K:K) -> 68326776
A5: Avg EV Growth Rate | B5: =SUM('master raw data'!U:U) -> 76803.55
A6: Average EV Range (km) | B6: =AVERAGE('n-table'!N:N) -> 1.342239

Sheet pv-n
A1: years | B1: Sum of ev_sales
A2: 2010 | B2: 20139
A3: 2011 | B3: 68532
A4: 2012 | B4: 120099
A5: 2013 | B5: 229508
A6: 2014 | B6: 324688
A7: 2015 | B7: 530272
A8: 2016 | B8: 741256
A9: 2017 | B9: 1343059
A10: 2018 | B10: 1922263
A11: 2019 | B11: 2034750
A12: 2020 | B12: 2989469
A13: 2021 | B13: 6503062
... A17: 2025 | B17: 19673169
A18: year | B18: (All)
A20: country | B20: Sum of ev_sales | C20: ev_market_share
A21: China | B21: 46544667 | C21: 436.47
A22: Germany | B22: 4848735 | C22: 475.5
A23: Netherlands | B23: 820328 | C23: 581.52
A24: Norway | B24: 923061 | C24: 1611.07
A25: Sweden | B25: 908473 | C25: 835.28
A26: year | B26: (All)
A28: Continents | B28: Average of ev_sales
A29: APAC | B29: 172602.48
A30: Europe | B30: 23580.625
A31: North America | B31: 69475.986
A32: Oceania | B32: 10581.188
A33: South America | B33: 5306.3125
A37: region | B37: Average of EV Market Share (%) | C37: Average of ICE Sales (Petrol + Diesel)
A38: 2010 | B38: 0.00028945696 | C38: 0.99971054
A39: 2011 | B39: 0.0013835383 | C39: 0.99861646
A40: 2012 | B40: 0.0024550467 | C40: 0.99754495
A41: 2013 | B41: 0.0056790485 | C41: 0.99432095
A42: 2014 | B42: 0.0088927554 | C42: 0.99110724
A43: 2015 | B43: 0.011487138 | C43: 0.98851286
A44: 2016 | B44: 0.014164086 | C44: 0.98583591
A45: 2017 | B45: 0.020637712 | C45: 0.97936229
A46: 2018 | B46: 0.027719772 | C46: 0.97228023
A47: 2019 | B47: 0.040675001 | C47: 0.959325
A48: 2020 | B48: 0.075827967 | C48: 0.92417203
...

Sheet n-table
A1: country | B1: region | C1: year | D1: vehicle_segment | E1: powertrain_type | F1: ev_sales | G1: petrol_car_sales | H1: diesel_car_sales | I1: total_vehicle_sales | J1: ev_market_share | K1: charging_stations | L1: fast_chargers_share | M1: avg_ev_range_km | N1: fuel_price_usd_per_liter | O1: electricity_price_usd_per_kwh | P1: gdp_per_capita | Q1: urban_population_percent | R1: co2_emissions_transport_mt | S1: ev_subsidy_usd | T1: emission_regulation_score | U1: ev_growth_rate_yoy | V1: is_ev_dominant | W1: EV Market Share (%) | X1: petrol_car Market Share | Y1: desil_car Market Share | Z1: ICE Sales (Petrol + Diesel) | AA1: ev_vs_ice_ratio
A2: Australia | B2: Oceania | C2: 2010 | D2: commercial | E2: ICE | F2: 5 | G2: 92877 | H2: 61921 | I2: 154803 | J2: 0 | K2: 0 | L2: 0 | M2: 124 | N2: 1.09 | O2: 0.149 | P2: 51977 | Q2: 88.8 | R2: 88.7 | S2: 0 | T2: 30.4 | U2: 0 | V2: 0 | W2: =EV_Data[[#This Row],[ev_sales]]/EV_Data[[#This Row],[total_vehicle_sales]] -> 3.2299116e-05 | X2: =EV_Data[[#This Row],[petrol_car_sales]]/EV_Data[[#This Row],[total_vehicle_sales]] -> 0.59996899 | Y2: =EV_Data[[#This Row],[diesel_car_sales]]/EV_Data[[#This Row],[total_vehicle_sales]] -> 0.39999871 | Z2: =EV_Data[[#This Row],[petrol_car Market Share]]+EV_Data[[#This Row],[desil_car Market Share]] -> 0.9999677
A3: Australia | B3: Oceania | C3: 2010 | D3: mass_market | E3: ICE | F3: 57 | G3: 535933 | H3: 73089 | I3: 609079 | J3: 0.01 | K3: 0 | L3: 0 | M3: 124 | N3: 1.09 | O3: 0.149 | P3: 51977 | Q3: 88.8 | R3: 88.7 | S3: 0 | T3: 30.4 | U3: 0 | V3: 0 | W3: =EV_Data[[#This Row],[ev_sales]]/EV_Data[[#This Row],[total_vehicle_sales]] -> 9.3583919e-05 | X3: =EV_Data[[#This Row],[petrol_car_sales]]/EV_Data[[#This Row],[total_vehicle_sales]] -> 0.8799072 | Y3: =EV_Data[[#This Row],[diesel_car_sales]]/EV_Data[[#This Row],[total_vehicle_sales]] -> 0.11999921 | Z3: =EV_Data[[#This Row],[petrol_car Market Share]]+EV_Data[[#This Row],[desil_car Market Share]] -> 0.99990642
A4: Australia | B4: Oceania | C4: 2010 | D4: premium | E4: ICE | F4: 37 | G4: 235282 | H4: 20462 | I4: 255781 | J4: 0.01 | K4: 0 | L4: 0 | M4: 124 | N4: 1.09 | O4: 0.149 | P4: 51977 | Q4: 88.8 | R4: 88.7 | S4: 0 | T4: 30.4 | U4: 0 | V4: 0 | W4: =EV_Data[[#This Row],[ev_sales]]/EV_Data[[#This Row],[total_vehicle_sales]] -> 0.000144655 | X4: =EV_Data[[#This Row],[petrol_car_sales]]/EV_Data[[#This Row],[total_vehicle_sales]] -> 0.91985722 | Y4: =EV_Data[[#This Row],[diesel_car_sales]]/EV_Data[[#This Row],[total_vehicle_sales]] -> 0.079998123 | Z4: =EV_Data[[#This Row],[petrol_car Market Share]]+EV_Data[[#This Row],[desil_car Market Share]] -> 0.99985535
A5: Australia | B5: Oceania | C5: 2011 | D5: commercial | E5: ICE | F5: 11 | G5: 98092 | H5: 65395 | I5: 163498 | J5: 0.01 | K5: 105 | L5: 1.5 | M5: 133 | N5: 1.09 | O5: 0.163 | P5: 52807 | Q5: 88.9 | R5: 88.3 | S5: 0 | T5: 30.8 | U5: 120 | V5: 0 | W5: =EV_Data[[#This Row],[ev_sales]]/EV_Data[[#This Row],[total_vehicle_sales]] -> 6.727911e-05 | X5: =EV_Data[[#This Row],[petrol_car_sales]]/EV_Data[[#This Row],[total_vehicle_sales]] -> 0.59995841 | Y5: =EV_Data[[#This Row],[diesel_car_sales]]/EV_Data[[#This Row],[total_vehicle_sales]] -> 0.39997431 | Z5: =EV_Data[[#This Row],[petrol_car Market Share]]+EV_Data[[#This Row],[desil_car Market Share]] -> 0.99993272
A6: Australia | B6: Oceania | C6: 2011 | D6: mass_market | E6: ICE | F6: 129 | G6: 569679 | H6: 77684 | I6: 647492 | J6: 0.02 | K6: 105 | L6: 1.5 | M6: 133 | N6: 1.09 | O6: 0.163 | P6: 52807 | Q6: 88.9 | R6: 88.3 | S6: 0 | T6: 30.8 | U6: 126.32 | V6: 0 | W6: =EV_Data[[#This Row],[ev_sales]]/EV_Data[[#This Row],[total_vehicle_sales]] -> 0.00019923026 | X6: =EV_Data[[#This Row],[petrol_car_sales]]/EV_Data[[#This Row],[total_vehicle_sales]] -> 0.879824 | Y6: =EV_Data[[#This Row],[diesel_car_sales]]/EV_Data[[#This Row],[total_vehicle_sales]] -> 0.11997677 | Z6: =EV_Data[[#This Row],[petrol_car Market Share]]+EV_Data[[#This Row],[desil_car Market Share]] -> 0.99980077
A7: Australia | B7: Oceania | C7: 2011 | D7: premium | E7: ICE | F7: 80 | G7: 252643 | H7: 21969 | I7: 274692 | J7: 0.03 | K7: 105 | L7: 1.5 | M7: 133 | N7: 1.09 | O7: 0.163 | P7: 52807 | Q7: 88.9 | R7: 88.3 | S7: 0 | T7: 30.8 | U7: 116.22 | V7: 0 | W7: =EV_Data[[#This Row],[ev_sales]]/EV_Data[[#This Row],[total_vehicle_sales]] -> 0.00029123527 | X7: =EV_Data[[#This Row],[petrol_car_sales]]/EV_Data[[#This Row],[total_vehicle_sales]] -> 0.91973192 | Y7: =EV_Data[[#This Row],[diesel_car_sales]]/EV_Data[[#This Row],[total_vehicle_sales]] -> 0.079976847 | Z7: =EV_Data[[#This Row],[petrol_car Market Share]]+EV_Data[[#This Row],[desil_car Market Share]] -> 0.99970876
A8: Australia | B8: Oceania | C8: 2012 | D8: commercial | E8: ICE | F8: 17 | G8: 96466 | H8: 64310 | I8: 160793 | J8: 0.01 | K8: 191 | L8: 3.3 | M8: 135 | N8: 1.067 | O8: 0.177 | P8: 54075 | Q8: 88.5 | R8: 89.5 | S8: 0 | T8: 31.6 | U8: 84.39 | V8: 0 | W8: =EV_Data[[#This Row],[ev_sales]]/EV_Data[[#This Row],[total_vehicle_sales]] -> 0.000105726 | X8: =EV_Data[[#This Row],[petrol_car_sales]]/EV_Data[[#This Row],[total_vehicle_sales]] -> 0.59993905 | Y8: =EV_Data[[#This Row],[diesel_car_sales]]/EV_Data[[#This Row],[total_vehicle_sales]] -> 0.39995522 | Z8: =EV_Data[[#This Row],[petrol_car Market Share]]+EV_Data[[#This Row],[desil_car Market Share]] -> 0.99989427
A9: Australia | B9: Oceania | C9: 2012 | D9: mass_market | E9: ICE | F9: 195 | G9: 571555 | H9: 77939 | I9: 649689 | J9: 0.03 | K9: 191 | L9: 3.3 | M9: 135 | N9: 1.067 | O9: 0.177 | P9: 54075 | Q9: 88.5 | R9: 89.5 | S9: 0 | T9: 31.6 | U9: 51.16 | V9: 0 | W9: =EV_Data[[#This Row],[ev_sales]]/EV_Data[[#This Row],[total_vehicle_sales]] -> 0.00030014361 | X9: =EV_Data[[#This Row],[petrol_car_sales]]/EV_Data[[#This Row],[total_vehicle_sales]] -> 0.8797363 | Y9: =EV_Data[[#This Row],[diesel_car_sales]]/EV_Data[[#This Row],[total_vehicle_sales]] -> 0.11996355 | Z9: =EV_Data[[#This Row],[petrol_car Market Share]]+EV_Data[[#This Row],[desil_car Market Share]] -> 0.99969986
A10: Australia | B10: Oceania | C10: 2012 | D10: premium | E10: ICE | F10: 117 | G10: 246448 | H10: 21430 | I10: 267995 | J10: 0.04 | K10: 191 | L10: 3.3 | M10: 135 | N10: 1.067 | O10: 0.177 | P10: 54075 | Q10: 88.5 | R10: 89.5 | S10: 0 | T10: 31.6 | U10: 77.82 | V10: 0 | W10: =EV_Data[[#This Row],[ev_sales]]/EV_Data[[#This Row],[total_vehicle_sales]] -> 0.00043657531 | X10: =EV_Data[[#This Row],[petrol_car_sales]]/EV_Data[[#This Row],[total_vehicle_sales]] -> 0.91959925 | Y10: =EV_Data[[#This Row],[diesel_car_sales]]/EV_Data[[#This Row],[total_vehicle_sales]] -> 0.079964178 | Z10: =EV_Data[[#This Row],[petrol_car Market Share]]+EV_Data[[#This Row],[desil_car Market Share]] -> 0.99956342
A11: Australia | B11: Oceania | C11: 2013 | D11: commercial | E11: ICE | F11: 36 | G11: 101461 | H11: 67640 | I11: 169137 | J11: 0.02 | K11: 306 | L11: 5 | M11: 143 | N11: 1.033 | O11: 0.192 | P11: 55582 | Q11: 89.6 | R11: 90 | S11: 0 | T11: 33.2 | U11: 93.1 | V11: 0 | W11: =EV_Data[[#This Row],[ev_sales]]/EV_Data[[#This Row],[total_vehicle_sales]] -> 0.00021284521 | X11: =EV_Data[[#This Row],[petrol_car_sales]]/EV_Data[[#This Row],[total_vehicle_sales]] -> 0.59987466 | Y11: =EV_Data[[#This Row],[diesel_car_sales]]/EV_Data[[#This Row],[total_vehicle_sales]] -> 0.3999125 | Z11: =EV_Data[[#This Row],[petrol_car Market Share]]+EV_Data[[#This Row],[desil_car Market Share]] -> 0.99978715
A12: Australia | B12: Oceania | C12: 2013 | D12: mass_market | E12: ICE | F12: 400 | G12: 586920 | H12: 80035 | I12: 667355 | J12: 0.06 | K12: 306 | L12: 5 | M12: 143 | N12: 1.033 | O12: 0.192 | P12: 55582 | Q12: 89.6 | R12: 90 | S12: 0 | T12: 33.2 | U12: 105.13 | V12: 0 | W12: =EV_Data[[#This Row],[ev_sales]]/EV_Data[[#This Row],[total_vehicle_sales]] -> 0.00059938114 | X12: =EV_Data[[#This Row],[petrol_car_sales]]/EV_Data[[#This Row],[total_vehicle_sales]] -> 0.87947195 | Y12: =EV_Data[[#This Row],[diesel_car_sales]]/EV_Data[[#This Row],[total_vehicle_sales]] -> 0.11992867 | Z12: =EV_Data[[#This Row],[petrol_car Market Share]]+EV_Data[[#This Row],[desil_car Market Share]] -> 0.99940062
A13: Australia | B13: Oceania | C13: 2013 | D13: premium | E13: ICE | F13: 242 | G13: 256088 | H13: 22269 | I13: 278599 | J13: 0.09 | K13: 306 | L13: 5 | M13: 143 | N13: 1.033 | O13: 0.192 | P13: 55582 | Q13: 89.6 | R13: 90 | S13: 0 | T13: 33.2 | U13: 106.84 | V13: 0 | W13: =EV_Data[[#This Row],[ev_sales]]/EV_Data[[#This Row],[total_vehicle_sales]] -> 0.00086863198 | X13: =EV_Data[[#This Row],[petrol_car_sales]]/EV_Data[[#This Row],[total_vehicle_sales]] -> 0.91919928 | Y13: =EV_Data[[#This Row],[diesel_car_sales]]/EV_Data[[#This Row],[total_vehicle_sales]] -> 0.079932089 | Z13: =EV_Data[[#This Row],[petrol_car Market Share]]+EV_Data[[#This Row],[desil_car Market Share]] -> 0.99913137
... A709: Norway | B709: Europe | C709: 2021 | D709: premium | E709: BEV | F709: 42451 | G709: 2055 | H709: 179 | I709: 44685 | J709: 95 | K709: 19829 | L709: 30.1 | M709: 395 | N709: 2.063 | O709: 0.131 | P709: 95275 | Q709: 82.8 | R709: 7.7 | S709: 0 | T709: 92.2 | U709: 51.45 | V709: 1 | W709: =EV_Data[[#This Row],[ev_sales]]/EV_Data[[#This Row],[total_vehicle_sales]] -> 0.95000559 | X709: =EV_Data[[#This Row],[petrol_car_sales]]/EV_Data[[#This Row],[total_vehicle_sales]] -> 0.045988587 | Y709: =EV_Data[[#This Row],[diesel_car_sales]]/EV_Data[[#This Row],[total_vehicle_sales]] -> 0.0040058185 | Z709: =EV_Data[[#This Row],[petrol_car Market Share]]+EV_Data[[#This Row],[desil_car Market Share]] -> 0.049994405
A710: Norway | B710: Europe | C710: 2022 | D710: commercial | E710: ICE | F710: 7229 | G710: 9462 | H710: 6308 | I710: 22999 | J710: 31.43 | K710: 24419 | L710: 31.8 | M710: 420 | N710: 2.143 | O710: 0.159 | P710: 103437 | Q710: 83.4 | R710: 7.2 | S710: 0 | T710: 95.60199999999999 | U710: 15.61 | V710: 0 | W710: =EV_Data[[#This Row],[ev_sales]]/EV_Data[[#This Row],[total_vehicle_sales]] -> 0.31431801 | X710: =EV_Data[[#This Row],[petrol_car_sales]]/EV_Data[[#This Row],[total_vehicle_sales]] -> 0.41140919 | Y710: =EV_Data[[#This Row],[diesel_car_sales]]/EV_Data[[#This Row],[total_vehicle_sales]] -> 0.27427279 | Z710: =EV_Data[[#This Row],[petrol_car Market Share]]+EV_Data[[#This Row],[desil_car Market Share]] -> 0.68568199
A711: Norway | B711: Europe | C711: 2022 | D711: mass_market | E711: BEV | F711: 82306 | G711: 8218 | H711: 1121 | I711: 91645 | J711: 89.81 | K711: 24419 | L711: 31.8 | M711: 420 | N711: 2.143 | O711: 0.159 | P711: 103437 | Q711: 83.4 | R711: 7.2 | S711: 0 | T711: 95.60199999999999 | U711: 14.06 | V711: 1 | W711: =EV_Data[[#This Row],[ev_sales]]/EV_Data[[#This Row],[total_vehicle_sales]] -> 0.89809591 | X711: =EV_Data[[#This Row],[petrol_car_sales]]/EV_Data[[#This Row],[total_vehicle_sales]] -> 0.089672104 | Y711: =EV_Data[[#This Row],[diesel_car_sales]]/EV_Data[[#This Row],[total_vehicle_sales]] -> 0.012231982 | Z711: =EV_Data[[#This Row],[petrol_car Market Share]]+EV_Data[[#This Row],[desil_car Market Share]] -> 0.10190409
A712: Norway | B712: Europe | C712: 2022 | D712: premium | E712: BEV | F712: 36110 | G712: 1748 | H712: 152 | I712: 38010 | J712: 95 | K712: 24419 | L712: 31.8 | M712: 420 | N712: 2.143 | O712: 0.159 | P712: 103437 | Q712: 83.4 | R712: 7.2 | S712: 0 | T712: 95.60199999999999 | U712: -14.94 | V712: 1 | W712: =EV_Data[[#This Row],[ev_sales]]/EV_Data[[#This Row],[total_vehicle_sales]] -> 0.95001315 | X712: =EV_Data[[#This Row],[petrol_car_sales]]/EV_Data[[#This Row],[total_vehicle_sales]] -> 0.045987898 | Y712: =EV_Data[[#This Row],[diesel_car_sales]]/EV_Data[[#This Row],[total_vehicle_sales]] -> 0.0039989476 | Z712: =EV_Data[[#This Row],[petrol_car Market Share]]+EV_Data[[#This Row],[desil_car Market Share]] -> 0.049986846
A713: Norway | B713: Europe | C713: 2023 | D713: commercial | E713: ICE | F713: 6780 | G713: 9069 | H713: 6804 | I713: 22653 | J713: 29.93 | K713: 29628 | L713: 32.9 | M713: 442 | N713: 2.153 | O713: 0.168 | P713: 100025 | Q713: 83.5 | R713: 6.7 | S713: 0 | T713: 95.6 | U713: -6.21 | V713: 0 | W713: =EV_Data[[#This Row],[ev_sales]]/EV_Data[[#This Row],[total_vehicle_sales]] -> 0.29929811 | X713: =EV_Data[[#This Row],[petrol_car_sales]]/EV_Data[[#This Row],[total_vehicle_sales]] -> 0.40034433 | Y713: =EV_Data[[#This Row],[diesel_car_sales]]/EV_Data[[#This Row],[total_vehicle_sales]] -> 0.30035757 | Z713: =EV_Data[[#This Row],[petrol_car Market Share]]+EV_Data[[#This Row],[desil_car Market Share]] -> 0.70070189
A714: Norway | B714: Europe | C714: 2023 | D714: mass_market | E714: BEV | F714: 79933 | G714: 7450 | H714: 3131 | I714: 90514 | J714: 88.31 | K714: 29628 | L714: 32.9 | M714: 442 | N714: 2.153 | O714: 0.168 | P714: 100025 | Q714: 83.5 | R714: 6.7 | S714: 0 | T714: 95.6 | U714: -2.88 | V714: 1 | W714: =EV_Data[[#This Row],[ev_sales]]/EV_Data[[#This Row],[total_vehicle_sales]] -> 0.88310096 | X714: =EV_Data[[#This Row],[petrol_car_sales]]/EV_Data[[#This Row],[total_vehicle_sales]] -> 0.082307709 | Y714: =EV_Data[[#This Row],[diesel_car_sales]]/EV_Data[[#This Row],[total_vehicle_sales]] -> 0.034591334 | Z714: =EV_Data[[#This Row],[petrol_car Market Share]]+EV_Data[[#This Row],[desil_car Market Share]] -> 0.11689904
A715: Norway | B715: Europe | C715: 2023 | D715: premium | E715: BEV | F715: 35655 | G715: 1727 | H715: 150 | I715: 37532 | J715: 95 | K715: 29628 | L715: 32.9 | M715: 442 | N715: 2.153 | O715: 0.168 | P715: 100025 | Q715: 83.5 | R715: 6.7 | S715: 0 | T715: 95.6 | U715: -1.26 | V715: 1 | W715: =EV_Data[[#This Row],[ev_sales]]/EV_Data[[#This Row],[total_vehicle_sales]] -> 0.94998934 | X715: =EV_Data[[#This Row],[petrol_car_sales]]/EV_Data[[#This Row],[total_vehicle_sales]] -> 0.046014068 | Y715: =EV_Data[[#This Row],[diesel_car_sales]]/EV_Data[[#This Row],[total_vehicle_sales]] -> 0.0039965896 | Z715: =EV_Data[[#This Row],[petrol_car Market Share]]+EV_Data[[#This Row],[desil_car Market Share]] -> 0.050010658
A716: Norway | B716: Europe | C716: 2024 | D716: commercial | E716: ICE | F716: 6792 | G716: 10069 | H716: 6713 | I716: 23574 | J716: 28.81 | K716: 33158 | L716: 31.7 | M716: 481 | N716: 2.09 | O716: 0.155 | P716: 94974 | Q716: 83.5 | R716: 6 | S716: 0 | T716: 95.60199999999999 | U716: 0.18 | V716: 0 | W716: =EV_Data[[#This Row],[ev_sales]]/EV_Data[[#This Row],[total_vehicle_sales]] -> 0.28811402 | X716: =EV_Data[[#This Row],[petrol_car_sales]]/EV_Data[[#This Row],[total_vehicle_sales]] -> 0.4271231 | Y716: =EV_Data[[#This Row],[diesel_car_sales]]/EV_Data[[#This Row],[total_vehicle_sales]] -> 0.28476287 | Z716: =EV_Data[[#This Row],[petrol_car Market Share]]+EV_Data[[#This Row],[desil_car Market Share]] -> 0.71188598
A717: Norway | B717: Europe | C717: 2024 | D717: mass_market | E717: BEV | F717: 82124 | G717: 10471 | H717: 2007 | I717: 94602 | J717: 86.81 | K717: 33158 | L717: 31.7 | M717: 481 | N717: 2.09 | O717: 0.155 | P717: 94974 | Q717: 83.5 | R717: 6 | S717: 0 | T717: 95.60199999999999 | U717: 2.74 | V717: 1 | W717: =EV_Data[[#This Row],[ev_sales]]/EV_Data[[#This Row],[total_vehicle_sales]] -> 0.86810004 | X717: =EV_Data[[#This Row],[petrol_car_sales]]/EV_Data[[#This Row],[total_vehicle_sales]] -> 0.11068476 | Y717: =EV_Data[[#This Row],[diesel_car_sales]]/EV_Data[[#This Row],[total_vehicle_sales]] -> 0.021215196 | Z717: =EV_Data[[#This Row],[petrol_car Market Share]]+EV_Data[[#This Row],[desil_car Market Share]] -> 0.13189996
A718: Norway | B718: Europe | C718: 2024 | D718: premium | E718: BEV | F718: 36884 | G718: 1786 | H718: 155 | I718: 38825 | J718: 95 | K718: 33158 | L718: 31.7 | M718: 481 | N718: 2.09 | O718: 0.155 | P718: 94974 | Q718: 83.5 | R718: 6 | S718: 0 | T718: 95.60199999999999 | U718: 3.45 | V718: 1 | W718: =EV_Data[[#This Row],[ev_sales]]/EV_Data[[#This Row],[total_vehicle_sales]] -> 0.95000644 | X718: =EV_Data[[#This Row],[petrol_car_sales]]/EV_Data[[#This Row],[total_vehicle_sales]] -> 0.046001288 | Y718: =EV_Data[[#This Row],[diesel_car_sales]]/EV_Data[[#This Row],[total_vehicle_sales]] -> 0.003992273 | Z718: =EV_Data[[#This Row],[petrol_car Market Share]]+EV_Data[[#This Row],[desil_car Market Share]] -> 0.049993561
A719: Norway | B719: Europe | C719: 2025 | D719: commercial | E719: ICE | F719: 7082 | G719: 9845 | H719: 6563 | I719: 23490 | J719: 30.15 | K719: 35915 | L719: 32.2 | M719: 507 | N719: 2.04 | O719: 0.144 | P719: 96351 | Q719: 84.3 | R719: 5.4 | S719: 0 | T719: 95.60199999999999 | U719: 4.27 | V719: 0 | W719: =EV_Data[[#This Row],[ev_sales]]/EV_Data[[#This Row],[total_vehicle_sales]] -> 0.30149 | X719: =EV_Data[[#This Row],[petrol_car_sales]]/EV_Data[[#This Row],[total_vehicle_sales]] -> 0.41911452 | Y719: =EV_Data[[#This Row],[diesel_car_sales]]/EV_Data[[#This Row],[total_vehicle_sales]] -> 0.27939549 | Z719: =EV_Data[[#This Row],[petrol_car Market Share]]+EV_Data[[#This Row],[desil_car Market Share]] -> 0.69851
A720: Norway | B720: Europe | C720: 2025 | D720: mass_market | E720: BEV | F720: 80945 | G720: 11461 | H720: 1563 | I720: 93969 | J720: 86.14 | K720: 35915 | L720: 32.2 | M720: 507 | N720: 2.04 | O720: 0.144 | P720: 96351 | Q720: 84.3 | R720: 5.4 | S720: 0 | T720: 95.60199999999999 | U720: -1.44 | V720: 1 | W720: =EV_Data[[#This Row],[ev_sales]]/EV_Data[[#This Row],[total_vehicle_sales]] -> 0.8614011 | X720: =EV_Data[[#This Row],[petrol_car_sales]]/EV_Data[[#This Row],[total_vehicle_sales]] -> 0.12196575 | Y720: =EV_Data[[#This Row],[diesel_car_sales]]/EV_Data[[#This Row],[total_vehicle_sales]] -> 0.016633145 | Z720: =EV_Data[[#This Row],[petrol_car Market Share]]+EV_Data[[#This Row],[desil_car Market Share]] -> 0.1385989
A721: Norway | B721: Europe | C721: 2025 | D721: premium | E721: BEV | F721: 37238 | G721: 1803 | H721: 157 | I721: 39198 | J721: 95 | K721: 35915 | L721: 32.2 | M721: 507 | N721: 2.04 | O721: 0.144 | P721: 96351 | Q721: 84.3 | R721: 5.4 | S721: 0 | T721: 95.60199999999999 | U721: 0.96 | V721: 1 | W721: =EV_Data[[#This Row],[ev_sales]]/EV_Data[[#This Row],[total_vehicle_sales]] -> 0.94999745 | X721: =EV_Data[[#This Row],[petrol_car_sales]]/EV_Data[[#This Row],[total_vehicle_sales]] -> 0.045997245 | Y721: =EV_Data[[#This Row],[diesel_car_sales]]/EV_Data[[#This Row],[total_vehicle_sales]] -> 0.0040053064 | Z721: =EV_Data[[#This Row],[petrol_car Market Share]]+EV_Data[[#This Row],[desil_car Market Share]] -> 0.050002551
A722: Poland | B722: Europe | C722: 2010 | D722: commercial | E722: ICE | F722: 5 | G722: 30458 | H722: 20309 | I722: 50772 | J722: 0.01 | K722: 0 | L722: 0 | M722: 111 | N722: 1.26 | O722: 0.143 | P722: 12774 | Q722: 60.9 | R722: 42.9 | S722: 0 | T722: 35.5 | U722: 0 | V722: 0 | W722: =EV_Data[[#This Row],[ev_sales]]/EV_Data[[#This Row],[total_vehicle_sales]] -> 9.8479477e-05 | X722: =EV_Data[[#This Row],[petrol_car_sales]]/EV_Data[[#This Row],[total_vehicle_sales]] -> 0.59989758 | Y722: =EV_Data[[#This Row],[diesel_car_sales]]/EV_Data[[#This Row],[total_vehicle_sales]] -> 0.40000394 | Z722: =EV_Data[[#This Row],[petrol_car Market Share]]+EV_Data[[#This Row],[desil_car Market Share]] -> 0.99990152
A723: Poland | B723: Europe | C723: 2010 | D723: mass_market | E723: ICE | F723: 15 | G723: 179802 | H723: 24520 | I723: 204337 | J723: 0.01 | K723: 0 | L723: 0 | M723: 111 | N723: 1.26 | O723: 0.143 | P723: 12774 | Q723: 60.9 | R723: 42.9 | S723: 0 | T723: 35.5 | U723: 0 | V723: 0 | W723: =EV_Data[[#This Row],[ev_sales]]/EV_Data[[#This Row],[total_vehicle_sales]] -> 7.3408144e-05 | X723: =EV_Data[[#This Row],[petrol_car_sales]]/EV_Data[[#This Row],[total_vehicle_sales]] -> 0.87992875 | Y723: =EV_Data[[#This Row],[diesel_car_sales]]/EV_Data[[#This Row],[total_vehicle_sales]] -> 0.11999785 | Z723: =EV_Data[[#This Row],[petrol_car Market Share]]+EV_Data[[#This Row],[desil_car Market Share]] -> 0.99992659
A724: Poland | B724: Europe | C724: 2010 | D724: premium | E724: ICE | F724: 10 | G724: 77444 | H724: 6735 | I724: 84189 | J724: 0.01 | K724: 0 | L724: 0 | M724: 111 | N724: 1.26 | O724: 0.143 | P724: 12774 | Q724: 60.9 | R724: 42.9 | S724: 0 | T724: 35.5 | U724: 0 | V724: 0 | W724: =EV_Data[[#This Row],[ev_sales]]/EV_Data[[#This Row],[total_vehicle_sales]] -> 0.00011878036 | X724: =EV_Data[[#This Row],[petrol_car_sales]]/EV_Data[[#This Row],[total_vehicle_sales]] -> 0.91988265 | Y724: =EV_Data[[#This Row],[diesel_car_sales]]/EV_Data[[#This Row],[total_vehicle_sales]] -> 0.079998575 | Z724: =EV_Data[[#This Row],[petrol_car Market Share]]+EV_Data[[#This Row],[desil_car Market Share]] -> 0.99988122
A725: Poland | B725: Europe | C725: 2011 | D725: commercial | E725: ICE | F725: 5 | G725: 30688 | H725: 20461 | I725: 51154 | J725: 0.01 | K725: 33 | L725: 1.1 | M725: 133 | N725: 1.22 | O725: 0.142 | P725: 12432 | Q725: 60.4 | R725: 43.5 | S725: 461 | T725: 36.3 | U725: 0 | V725: 0 | W725: =EV_Data[[#This Row],[ev_sales]]/EV_Data[[#This Row],[total_vehicle_sales]] -> 9.7744067e-05 | X725: =EV_Data[[#This Row],[petrol_car_sales]]/EV_Data[[#This Row],[total_vehicle_sales]] -> 0.59991399 | Y725: =EV_Data[[#This Row],[diesel_car_sales]]/EV_Data[[#This Row],[total_vehicle_sales]] -> 0.39998827 | Z725: =EV_Data[[#This Row],[petrol_car Market Share]]+EV_Data[[#This Row],[desil_car Market Share]] -> 0.99990226
A726: Poland | B726: Europe | C726: 2011 | D726: mass_market | E726: ICE | F726: 20 | G726: 179407 | H726: 24465 | I726: 203892 | J726: 0.01 | K726: 33 | L726: 1.1 | M726: 133 | N726: 1.22 | O726: 0.142 | P726: 12432 | Q726: 60.4 | R726: 43.5 | S726: 461 | T726: 36.3 | U726: 33.33 | V726: 0 | W726: =EV_Data[[#This Row],[ev_sales]]/EV_Data[[#This Row],[total_vehicle_sales]] -> 9.8091146e-05 | X726: =EV_Data[[#This Row],[petrol_car_sales]]/EV_Data[[#This Row],[total_vehicle_sales]] -> 0.87991191 | Y726: =EV_Data[[#This Row],[diesel_car_sales]]/EV_Data[[#This Row],[total_vehicle_sales]] -> 0.11998999 | Z726: =EV_Data[[#This Row],[petrol_car Market Share]]+EV_Data[[#This Row],[desil_car Market Share]] -> 0.99990191
A727: Poland | B727: Europe | C727: 2011 | D727: premium | E727: ICE | F727: 12 | G727: 76516 | H727: 6654 | I727: 83182 | J727: 0.01 | K727: 33 | L727: 1.1 | M727: 133 | N727: 1.22 | O727: 0.142 | P727: 12432 | Q727: 60.4 | R727: 43.5 | S727: 461 | T727: 36.3 | U727: 20 | V727: 0 | W727: =EV_Data[[#This Row],[ev_sales]]/EV_Data[[#This Row],[total_vehicle_sales]] -> 0.00014426198 | X727: =EV_Data[[#This Row],[petrol_car_sales]]/EV_Data[[#This Row],[total_vehicle_sales]] -> 0.91986247 | Y727: =EV_Data[[#This Row],[diesel_car_sales]]/EV_Data[[#This Row],[total_vehicle_sales]] -> 0.079993268 | Z727: =EV_Data[[#This Row],[petrol_car Market Share]]+EV_Data[[#This Row],[desil_car Market Share]] -> 0.99985574
A728: Poland | B728: Europe | C728: 2012 | D728: commercial | E728: ICE | F728: 10 | G728: 29335 | H728: 19562 | I728: 48907 | J728: 0.02 | K728: 69 | L728: 1.9 | M728: 148 | N728: 1.187 | O728: 0.14 | P728: 12537 | Q728: 60.5 | R728: 44.9 | S728: 908 | T728: 37.8 | U728: 41.42 | V728: 0 | W728: =EV_Data[[#This Row],[ev_sales]]/EV_Data[[#This Row],[total_vehicle_sales]] -> 0.00020446971 | X728: =EV_Data[[#This Row],[petrol_car_sales]]/EV_Data[[#This Row],[total_vehicle_sales]] -> 0.59981189 | Y728: =EV_Data[[#This Row],[diesel_car_sales]]/EV_Data[[#This Row],[total_vehicle_sales]] -> 0.39998364 | Z728: =EV_Data[[#This Row],[petrol_car Market Share]]+EV_Data[[#This Row],[desil_car Market Share]] -> 0.99979553
A729: Poland | B729: Europe | C729: 2012 | D729: mass_market | E729: ICE | F729: 39 | G729: 170818 | H729: 23293 | I729: 194150 | J729: 0.02 | K729: 69 | L729: 1.9 | M729: 148 | N729: 1.187 | O729: 0.14 | P729: 12537 | Q729: 60.5 | R729: 44.9 | S729: 908 | T729: 37.8 | U729: 61.25 | V729: 0 | W729: =EV_Data[[#This Row],[ev_sales]]/EV_Data[[#This Row],[total_vehicle_sales]] -> 0.00020087561 | X729: =EV_Data[[#This Row],[petrol_car_sales]]/EV_Data[[#This Row],[total_vehicle_sales]] -> 0.87982488 | Y729: =EV_Data[[#This Row],[diesel_car_sales]]/EV_Data[[#This Row],[total_vehicle_sales]] -> 0.11997425 | Z729: =EV_Data[[#This Row],[petrol_car Market Share]]+EV_Data[[#This Row],[desil_car Market Share]] -> 0.99979912
A730: Poland | B730: Europe | C730: 2012 | D730: premium | E730: ICE | F730: 24 | G730: 75579 | H730: 6572 | I730: 82175 | J730: 0.03 | K730: 69 | L730: 1.9 | M730: 148 | N730: 1.187 | O730: 0.14 | P730: 12537 | Q730: 60.5 | R730: 44.9 | S730: 908 | T730: 37.8 | U730: 54.92 | V730: 0 | W730: =EV_Data[[#This Row],[ev_sales]]/EV_Data[[#This Row],[total_vehicle_sales]] -> 0.00029205963 | X730: =EV_Data[[#This Row],[petrol_car_sales]]/EV_Data[[#This Row],[total_vehicle_sales]] -> 0.91973228 | Y730: =EV_Data[[#This Row],[diesel_car_sales]]/EV_Data[[#This Row],[total_vehicle_sales]] -> 0.079975662 | Z730: =EV_Data[[#This Row],[petrol_car Market Share]]+EV_Data[[#This Row],[desil_car Market Share]] -> 0.99970794
A731: Poland | B731: Europe | C731: 2013 | D731: commercial | E731: ICE | F731: 8 | G731: 29076 | H731: 19388 | I731: 48472 | J731: 0.02 | K731: 108 | L731: 3.2 | M731: 130 | N731: 1.153 | O731: 0.139 | P731: 12431 | Q731: 60.7 | R731: 46 | S731: 1382 | T731: 39.9 | U731: 16.96 | V731: 0 | W731: =EV_Data[[#This Row],[ev_sales]]/EV_Data[[#This Row],[total_vehicle_sales]] -> 0.00016504374 | X731: =EV_Data[[#This Row],[petrol_car_sales]]/EV_Data[[#This Row],[total_vehicle_sales]] -> 0.59985146 | Y731: =EV_Data[[#This Row],[diesel_car_sales]]/EV_Data[[#This Row],[total_vehicle_sales]] -> 0.3999835 | Z731: =EV_Data[[#This Row],[petrol_car Market Share]]+EV_Data[[#This Row],[desil_car Market Share]] -> 0.99983496
A732: Poland | B732: Europe | C732: 2013 | D732: mass_market | E732: ICE | F732: 39 | G732: 172737 | H732: 23555 | I732: 196331 | J732: 0.02 | K732: 108 | L732: 3.2 | M732: 130 | N732: 1.153 | O732: 0.139 | P732: 12431 | Q732: 60.7 | R732: 46 | S732: 1382 | T732: 39.9 | U732: 37.51 | V732: 0 | W732: =EV_Data[[#This Row],[ev_sales]]/EV_Data[[#This Row],[total_vehicle_sales]] -> 0.00019864413 | X732: =EV_Data[[#This Row],[petrol_car_sales]]/EV_Data[[#This Row],[total_vehicle_sales]] -> 0.8798254 | Y732: =EV_Data[[#This Row],[diesel_car_sales]]/EV_Data[[#This Row],[total_vehicle_sales]] -> 0.11997596 | Z732: =EV_Data[[#This Row],[petrol_car Market Share]]+EV_Data[[#This Row],[desil_car Market Share]] -> 0.99980136
A733: Poland | B733: Europe | C733: 2013 | D733: premium | E733: ICE | F733: 24 | G733: 75395 | H733: 6556 | I733: 81975 | J733: 0.03 | K733: 108 | L733: 3.2 | M733: 130 | N733: 1.153 | O733: 0.139 | P733: 12431 | Q733: 60.7 | R733: 46 | S733: 1382 | T733: 39.9 | U733: 33.89 | V733: 0 | W733: =EV_Data[[#This Row],[ev_sales]]/EV_Data[[#This Row],[total_vehicle_sales]] -> 0.00029277219 | X733: =EV_Data[[#This Row],[petrol_car_sales]]/EV_Data[[#This Row],[total_vehicle_sales]] -> 0.91973163 | Y733: =EV_Data[[#This Row],[diesel_car_sales]]/EV_Data[[#This Row],[total_vehicle_sales]] -> 0.079975602 | Z733: =EV_Data[[#This Row],[petrol_car Market Share]]+EV_Data[[#This Row],[desil_car Market Share]] -> 0.99970723
... A958: Sweden | B958: Europe | C958: 2024 | D958: premium | E958: BEV | F958: 54057 | G958: 18104 | H958: 1574 | I958: 73735 | J958: 73.31 | K958: 35576 | L958: 26.7 | M958: 466 | N958: 2 | O958: 0.155 | P958: 57305 | Q958: 88.8 | R958: 13.2 | S958: 0 | T958: 92.7 | U958: 5.44 | V958: 1 | W958: =EV_Data[[#This Row],[ev_sales]]/EV_Data[[#This Row],[total_vehicle_sales]] -> 0.73312538 | X958: =EV_Data[[#This Row],[petrol_car_sales]]/EV_Data[[#This Row],[total_vehicle_sales]] -> 0.2455279 | Y958: =EV_Data[[#This Row],[diesel_car_sales]]/EV_Data[[#This Row],[total_vehicle_sales]] -> 0.021346715 | Z958: =EV_Data[[#This Row],[petrol_car Market Share]]+EV_Data[[#This Row],[desil_car Market Share]] -> 0.26687462
A959: Sweden | B959: Europe | C959: 2025 | D959: commercial | E959: ICE | F959: 8259 | G959: 22172 | H959: 14781 | I959: 45212 | J959: 18.27 | K959: 45844 | L959: 26.6 | M959: 486 | N959: 1.93 | O959: 0.141 | P959: 61242 | Q959: 89 | R959: 12.2 | S959: 0 | T959: 95.60199999999999 | U959: 6.62 | V959: 0 | W959: =EV_Data[[#This Row],[ev_sales]]/EV_Data[[#This Row],[total_vehicle_sales]] -> 0.18267274 | X959: =EV_Data[[#This Row],[petrol_car_sales]]/EV_Data[[#This Row],[total_vehicle_sales]] -> 0.49040078 | Y959: =EV_Data[[#This Row],[diesel_car_sales]]/EV_Data[[#This Row],[total_vehicle_sales]] -> 0.32692648 | Z959: =EV_Data[[#This Row],[petrol_car Market Share]]+EV_Data[[#This Row],[desil_car Market Share]] -> 0.81732726
...

Sheet dim_country
A1: country_id | B1: country | C1: region
A2: 1 | B2: Australia | C2: Oceania
A3: 2 | B3: Austria | C3: Europe
A4: 3 | B4: Belgium | C4: Europe
A5: 4 | B5: Brazil | C5: South America
A6: 5 | B6: Canada | C6: North America
A7: 6 | B7: China | C7: APAC
A8: 7 | B8: France | C8: Europe
A9: 8 | B9: Germany | C9: Europe
A10: 9 | B10: India | C10: APAC
A11: 10 | B11: Indonesia | C11: APAC
A12: 11 | B12: Italy | C12: Europe
A13: 12 | B13: Japan | C13: APAC
... A26: 25 | B26: United States | C26: North America

Sheet dim_date
A1: year_id | B1: year
A2: 1 | B2: 2010
A3: 2 | B3: 2011
A4: 3 | B4: 2012
A5: 4 | B5: 2013
A6: 5 | B6: 2014
A7: 6 | B7: 2015
A8: 7 | B8: 2016
A9: 8 | B9: 2017
A10: 9 | B10: 2018
A11: 10 | B11: 2019
A12: 11 | B12: 2020
A13: 12 | B13: 2021
... A17: 16 | B17: 2025
